Workbook
Name GeocodeAddressColumn_ToGeocode: 'To Geocode'!$B$1
Name GeocodeAddressColumn_Sheet1: Sheet1!$B$1
Name GeocodeAddressColumn_Sheet3: #REF!

Sheet Sheet1
A1: UID | B1: EngName | C1: Latitude | D1: Longitude | E1: HebName | G1: Rishon | H1: YS_id | I1: IsWord | J1: Notes | K1: Sourcing | L1: KaganID | M1: JGenID | N1: AltEng | O1: USBGN
A2: AF-00011 | B2: Herat | C2: 34.341944 | D2: 62.203056 | E2: הראת | I2: y | K2: Ketubah
A3: AF-00012 | B3: Hari River | C3: 34.65 | D3: 66.716667 | E3: הרי רוד | K3: Ketubah | N3: Harī Rōd
A4: AL-00011 | B4: Vlorë, Albania | C4: 40.466067 | D4: 19.491356 | E4: אבילונה | K4: SDM
A5: AL-00011 | B5: Vlorë, Albania | C5: 40.466067 | D5: 19.491356 | E5: אוילונה | K5: SDM
A6: AL-00012 | B6: Lezhë, Albania | C6: 41.786073 | D6: 19.646076 | E6: אלישו | J6: IDed by Bornstein | K6: SDM
A7: AL-00013 | B7: Nartë, Albania | C7: 40.499167 | D7: 19.457222 | E7: נארטא | K7: Pri Etz Hayim 1742 Intro
A8: AM-00001 | B8: Yerevan, Armenia | C8: 40.183333 | D8: 44.516667 | K8: JGen | M8: 4912 | N8: Yerevan, Erevan | O8: -2325645
A9: AM-00011 | B9: Tashir, Armenia | C9: 41.115965 | D9: 44.285778 | E9: וואראנסאווקע | K9: Kagan | L9: 2651
A10: AR-00000 | B10: Argentina | C10: -38.416097 | D10: -63.616672 | E10: ארגאנטינא | K10: VeZot LiYehudah
A11: AR-00000 | B11: Argentina | C11: -38.416097 | D11: -63.616672 | E11: ארגנטינא | K11: DivM
A12: AR-00000 | B12: Argentina | C12: -38.416097 | D12: -63.616672 | E12: ארגנטינה | K12: VeZot LiYehudah
A13: AR-00000 | B13: Argentina | C13: -38.416097 | D13: -63.616672 | E13: ארגענטינא | K13: IGMO
A14: AR-00001 | B14: Buenos Aires | C14: -34.603684 | D14: -58.381559 | E14: בואינוס איירעס
A15: AR-00001 | B15: Buenos Aires | C15: -34.603684 | D15: -58.381559 | E15: בונעס איירעס | K15: DivM
A16: AR-00001 | B16: Buenos Aires | C16: -34.603684 | D16: -58.381559 | E16: בונעס אירעס | K16: Prenum - Hemdat Yisrael
A17: AR-00001 | B17: Buenos Aires | C17: -34.603684 | D17: -58.381559 | E17: בוענאס איירעס | K17: Prenum 2325
A18: AR-00011 | B18: Moisés Ville, Argentina | C18: -30.714305 | D18: -61.469815 | E18: מאזעס-וויללע | K18: DivM
A19: AR-00011 | B19: Moisés Ville, Argentina | C19: -30.714305 | D19: -61.469815 | E19: מאזעסווילע
A20: AR-00011 | B20: Moisés Ville, Argentina | C20: -30.714305 | D20: -61.469815 | E20: מאזעסוילע | K20: Prenum 74
A21: AR-00011 | B21: Moisés Ville, Argentina | C21: -30.714305 | D21: -61.469815 | E21: קרית משה | K21: RAYK
A22: AR-00012 | B22: Rio de la Plata | C22: -35.194456 | D22: -56.741207 | E22: פלאטא | K22: DivM
A23: AR-00013 | B23: Córdoba, Argentina | C23: -31.416667 | D23: -64.183333 | E23: קארדובא | K23: Prenum 2325
A24: AR-00014 | B24: Quilmes, Argentina | C24: -34.716667 | D24: -58.266667 | E24: קילמעס | K24: Prenum 2325
A25: AR-00015 | B25: Rosaria, Argentina | C25: -32.9575 | D25: -60.639444 | E25: רוזאריא | K25: Prenum 2325
A26: AT-00000 | B26: Austria | C26: 47.516231 | D26: 14.550072 | E26: אושטרייך | G26: Y | K26: 15thCAshkenaz | M26: 760 | N26: Österreich [Ger], Austria [Eng, Pol, Rom, Sp, Ital, Lat], Ausztria [Hun], Avstriya [Rus, Ukr], Estraykh [Yid], Autriche [Fr], Rakousko [Cz], Rakúsko [Slov], Austrija [Bosn, Serb, Croa, Latv, Lith] | O26: -1974447
A27: AT-00000 | B27: Austria | C27: 47.516231 | D27: 14.550072 | E27: אושטריך | G27: Y | K27: 15thCAshkenaz | M27: 760 | N27: Österreich [Ger], Austria [Eng, Pol, Rom, Sp, Ital, Lat], Ausztria [Hun], Avstriya [Rus, Ukr], Estraykh [Yid], Autriche [Fr], Rakousko [Cz], Rakúsko [Slov], Austrija [Bosn, Serb, Croa, Latv, Lith] | O27: -1974447
A28: AT-00000 | B28: Austria | C28: 47.516231 | D28: 14.550072 | E28: ארץ הדמים | G28: Y | K28: 15thCAshkenaz | M28: 760 | N28: Österreich [Ger], Austria [Eng, Pol, Rom, Sp, Ital, Lat], Ausztria [Hun], Avstriya [Rus, Ukr], Estraykh [Yid], Autriche [Fr], Rakousko [Cz], Rakúsko [Slov], Austrija [Bosn, Serb, Croa, Latv, Lith] | O28: -1974447
A29: AT-00000 | B29: Austria | C29: 47.516231 | D29: 14.550072 | E29: מדינת בני חת | G29: Y | K29: 15thCAshkenaz | M29: 760 | N29: Österreich [Ger], Austria [Eng, Pol, Rom, Sp, Ital, Lat], Ausztria [Hun], Avstriya [Rus, Ukr], Estraykh [Yid], Autriche [Fr], Rakousko [Cz], Rakúsko [Slov], Austrija [Bosn, Serb, Croa, Latv, Lith] | O29: -1974447
A30: AT-00000 | B30: Austria | C30: 47.516231 | D30: 14.550072 | E30: עסטרייך | K30: JGen | M30: 760 | N30: Österreich [Ger], Austria [Eng, Pol, Rom, Sp, Ital, Lat], Ausztria [Hun], Avstriya [Rus, Ukr], Estraykh [Yid], Autriche [Fr], Rakousko [Cz], Rakúsko [Slov], Austrija [Bosn, Serb, Croa, Latv, Lith] | O30: -1974447
A31: AT-00001 | B31: Vienna | C31: 48.208174 | D31: 16.373819 | E31: ווידען | L31: 2827 | M31: 167 | N31: Wien [Ger], Vienna [Eng], Vienne [Fr], Vindobona [Lat], Videň [Cz], Viedeň [Slov], Bécs [Hung], Beč [Serb], Viena [Rom], Wiedeń [Pol], Vena [Rus], Viden' [Ukr], Vin [Yid] | O31: -1995499
A32: AT-00001 | B32: Vienna | C32: 48.208174 | D32: 16.373819 | E32: וויין | K32: חיים וחסד א | L32: 2827 | M32: 167 | N32: Wien [Ger], Vienna [Eng], Vienne [Fr], Vindobona [Lat], Videň [Cz], Viedeň [Slov], Bécs [Hung], Beč [Serb], Viena [Rom], Wiedeń [Pol], Vena [Rus], Viden' [Ukr], Vin [Yid] | O32: -1995499
A33: AT-00001 | B33: Vienna | C33: 48.208174 | D33: 16.373819 | E33: ווין | L33: 2827 | M33: 167 | N33: Wien [Ger], Vienna [Eng], Vienne [Fr], Vindobona [Lat], Videň [Cz], Viedeň [Slov], Bécs [Hung], Beč [Serb], Viena [Rom], Wiedeń [Pol], Vena [Rus], Viden' [Ukr], Vin [Yid] | O33: -1995499
A34: AT-00001 | B34: Vienna | C34: 48.208174 | D34: 16.373819 | E34: ווינא | L34: 2827 | M34: 167 | N34: Wien [Ger], Vienna [Eng], Vienne [Fr], Vindobona [Lat], Videň [Cz], Viedeň [Slov], Bécs [Hung], Beč [Serb], Viena [Rom], Wiedeń [Pol], Vena [Rus], Viden' [Ukr], Vin [Yid] | O34: -1995499
A35: AT-00001 | B35: Vienna | C35: 48.208174 | D35: 16.373819 | E35: וויעדן | L35: 2827 | M35: 167 | N35: Wien [Ger], Vienna [Eng], Vienne [Fr], Vindobona [Lat], Videň [Cz], Viedeň [Slov], Bécs [Hung], Beč [Serb], Viena [Rom], Wiedeń [Pol], Vena [Rus], Viden' [Ukr], Vin [Yid] | O35: -1995499
A36: AT-00001 | B36: Vienna | C36: 48.208174 | D36: 16.373819 | E36: וויעדען | L36: 2827 | M36: 167 | N36: Wien [Ger], Vienna [Eng], Vienne [Fr], Vindobona [Lat], Videň [Cz], Viedeň [Slov], Bécs [Hung], Beč [Serb], Viena [Rom], Wiedeń [Pol], Vena [Rus], Viden' [Ukr], Vin [Yid] | O36: -1995499
A37: AT-00001 | B37: Vienna | C37: 48.208174 | D37: 16.373819 | E37: וויעהן | K37: RSK | L37: 2827 | M37: 167 | N37: Wien [Ger], Vienna [Eng], Vienne [Fr], Vindobona [Lat], Videň [Cz], Viedeň [Slov], Bécs [Hung], Beč [Serb], Viena [Rom], Wiedeń [Pol], Vena [Rus], Viden' [Ukr], Vin [Yid] | O37: -1995499
A38: AT-00001 | B38: Vienna | C38: 48.208174 | D38: 16.373819 | E38: וויען | L38: 2827 | M38: 167 | N38: Wien [Ger], Vienna [Eng], Vienne [Fr], Vindobona [Lat], Videň [Cz], Viedeň [Slov], Bécs [Hung], Beč [Serb], Viena [Rom], Wiedeń [Pol], Vena [Rus], Viden' [Ukr], Vin [Yid] | O38: -1995499
A39: AT-00001 | B39: Vienna | C39: 48.208174 | D39: 16.373819 | E39: וין | K39: Prenum 878 | L39: 2827 | M39: 167 | N39: Wien [Ger], Vienna [Eng], Vienne [Fr], Vindobona [Lat], Videň [Cz], Viedeň [Slov], Bécs [Hung], Beč [Serb], Viena [Rom], Wiedeń [Pol], Vena [Rus], Viden' [Ukr], Vin [Yid] | O39: -1995499
A40: AT-00001 | B40: Vienna | C40: 48.208174 | D40: 16.373819 | E40: וינה | K40: Dor4 | L40: 2827 | M40: 167 | N40: Wien [Ger], Vienna [Eng], Vienne [Fr], Vindobona [Lat], Videň [Cz], Viedeň [Slov], Bécs [Hung], Beč [Serb], Viena [Rom], Wiedeń [Pol], Vena [Rus], Viden' [Ukr], Vin [Yid] | O40: -1995499
...

Sheet Ambiguous names

Sheet Pivot Table 2

Sheet To Geocode
A1: UID | B1: EngName | C1: Latitude | D1: Longitude | E1: HebName | G1: Rishon | H1: YS_id | I1: IsWord | J1: Notes | K1: Sourcing
A2: MapsTooltip - Hidden - StringFilter | B2: MapsLat - Hidden - NoFilter | C2: MapsLong - Hidden - NoFilter
E3: קוראסאו | K3: Ketubah: https://www.nli.org.il/en/discover/manuscripts/hebrew-manuscripts/viewerpage?vid=MANUSCRIPTS#d=[[PNX_MANUSCRIPTS990052916130205171-1,FL83181910]]
E4: קורסאו | K4: https://www.nli.org.il/en/discover/manuscripts/hebrew-manuscripts/viewerpage?vid=MANUSCRIPTS#d=[[PNX_MANUSCRIPTS990001491300205171-1,FL25515209]]
E5: וילים שטאד | K5: Ketubah: https://www.nli.org.il/en/discover/manuscripts/hebrew-manuscripts/viewerpage?vid=MANUSCRIPTS#d=[[PNX_MANUSCRIPTS990052916130205171-1,FL83181910]]
E6: ג'מאיקה | K6: יאשיהו פארדו - מזבח הזהב

Sheet Unidentified
A1: HebName | B1: IsWord | C1: Notes | D1: Sourcing | E1: KaganID | F1: JGenID | G1: Status
A2: קו"ו | D2: NBY | G2: Gave up | H2: =MATCH($A2,Sheet1!E:E,FALSE) -> 5399
A3: קריסלאווע | E3: 7892 | H3: =MATCH($A3,Sheet1!E:E,FALSE) -> 8373
A4: באשאן | C4: קדושת ישראל | D4: קצב3 | H4: =MATCH($A4,Sheet1!E:E,FALSE) -> 16911
A5: אומין | D5: DivreiHayim | G5: Gave up | H5: =MATCH($A5,Sheet1!E:E,FALSE) -> 19081
A6: ניזען | E6: 5276 | H6: =MATCH($A6,Sheet1!E:E,FALSE) -> 20452
A7: א דעגעש | E7: 7 | H7: =MATCH($A7,Sheet1!E:E,FALSE) -> #N/A
A8: א' גענץ | E8: 1 | H8: =MATCH($A8,Sheet1!E:E,FALSE) -> #N/A
A9: א' פאיע | D9: Hungarian Yeshivot | H9: =MATCH($A9,Sheet1!E:E,FALSE) -> #N/A
A10: א' פערעני | E10: 6 | H10: =MATCH($A10,Sheet1!E:E,FALSE) -> #N/A
A11: א"מ | D11: KS | G11: Gave up | H11: =MATCH($A11,Sheet1!E:E,FALSE) -> #N/A
A12: אבאד | E12: 10 | H12: =MATCH($A12,Sheet1!E:E,FALSE) -> #N/A
A13: אבאדאי | E13: 11 | H13: =MATCH($A13,Sheet1!E:E,FALSE) -> #N/A
A14: אבאכאוו | D14: 999 | H14: =MATCH($A14,Sheet1!E:E,FALSE) -> #N/A
A15: אביווא | E15: 23 | H15: =MATCH($A15,Sheet1!E:E,FALSE) -> #N/A
A16: אבילינע | E16: 25 | H16: =MATCH($A16,Sheet1!E:E,FALSE) -> #N/A
A17: אבער פעטישן | D17: MASZ | G17: Gave up | H17: =MATCH($A17,Sheet1!E:E,FALSE) -> #N/A
A18: אבראזעז | E18: 41 | H18: =MATCH($A18,Sheet1!E:E,FALSE) -> #N/A
A19: אבראט | D19: עיר מבצר | G19: Gave up | H19: =MATCH($A19,Sheet1!E:E,FALSE) -> #N/A
A20: אבראנקע | E20: 44 | H20: =MATCH($A20,Sheet1!E:E,FALSE) -> #N/A
A21: אברזידק | C21: עדות נאמנה | D21: קצב3 | H21: =MATCH($A21,Sheet1!E:E,FALSE) -> #N/A
A22: אברישארע | E22: 47 | H22: =MATCH($A22,Sheet1!E:E,FALSE) -> #N/A
A23: אגטינא | E23: 49 | H23: =MATCH($A23,Sheet1!E:E,FALSE) -> #N/A
A24: אגיזינסק | D24: 999 | H24: =MATCH($A24,Sheet1!E:E,FALSE) -> #N/A
A25: אגנע | E25: 50 | H25: =MATCH($A25,Sheet1!E:E,FALSE) -> #N/A
A26: אגראביטש | E26: 52 | H26: =MATCH($A26,Sheet1!E:E,FALSE) -> #N/A
A27: אדזאעט | E27: 63 | H27: =MATCH($A27,Sheet1!E:E,FALSE) -> #N/A
A28: אדזע | E28: 64 | H28: =MATCH($A28,Sheet1!E:E,FALSE) -> #N/A
A29: אדזשוד | E29: 65 | H29: =MATCH($A29,Sheet1!E:E,FALSE) -> #N/A
A30: אדיגפאלווא | E30: 66 | H30: =MATCH($A30,Sheet1!E:E,FALSE) -> #N/A
A31: אדער בערג אין גאליציען | D31: 1296 | G31: Gave up | H31: =MATCH($A31,Sheet1!E:E,FALSE) -> #N/A
A32: אדערסדארף | E32: 70 | H32: =MATCH($A32,Sheet1!E:E,FALSE) -> #N/A
A33: אדעשדארף | E33: 71 | H33: =MATCH($A33,Sheet1!E:E,FALSE) -> #N/A
A34: אדראכאוו | E34: 72 | H34: =MATCH($A34,Sheet1!E:E,FALSE) -> #N/A
A35: אדרעקקערעסטור | E35: 74 | H35: =MATCH($A35,Sheet1!E:E,FALSE) -> #N/A
A36: אהאט | E36: 75 | H36: =MATCH($A36,Sheet1!E:E,FALSE) -> #N/A
A37: אהאלאוו | E37: 77 | H37: =MATCH($A37,Sheet1!E:E,FALSE) -> #N/A
A38: אהיפאלא | E38: 78 | H38: =MATCH($A38,Sheet1!E:E,FALSE) -> #N/A
A39: אהרליך | D39: דברי חיים | H39: =MATCH($A39,Sheet1!E:E,FALSE) -> #N/A
A40: אהרשקוט, ארשקוט | C40: near Starňa, Slovakia | D40: 1200 | G40: Gave up | H40: =MATCH($A40,Sheet1!E:E,FALSE) -> #N/A
...
